2019-07-28 01:04:19 [scrapy.core.scraper] ERROR: Spider error processing <GET https://sh.fang.ke.com/loupan/pg36> (referer: https://sh.fang.ke.com/loupan/pg35)
Traceback (most recent call last):
  File "C:\Users\requests\Anaconda3\envs\spider\lib\site-packages\scrapy\utils\defer.py", line 102, in iter_errback
    yield next(it)
  File "C:\Users\requests\Anaconda3\envs\spider\lib\site-packages\scrapy\spidermiddlewares\offsite.py", line 30, in process_spider_output
    for x in result:
  File "C:\Users\requests\Anaconda3\envs\spider\lib\site-packages\scrapy\spidermiddlewares\referer.py", line 339, in <genexpr>
    return (_set_referer(r) for r in result or ())
  File "C:\Users\requests\Anaconda3\envs\spider\lib\site-packages\scrapy\spidermiddlewares\urllength.py", line 37, in <genexpr>
    return (r for r in result or () if _filter(r))
  File "C:\Users\requests\Anaconda3\envs\spider\lib\site-packages\scrapy\spidermiddlewares\depth.py", line 58, in <genexpr>
    return (r for r in result or () if _filter(r))
  File "C:\python\scrapy_win\beikeitem\beikeitem\spiders\beike.py", line 37, in parse_item
    number = response.xpath('//div[@class="resblock-have-find"]/span[@class="value"]/text()').extract()[0]
IndexError: list index out of range
2019-07-28 09:57:19 [scrapy.core.scraper] ERROR: Error downloading <GET https://xan.fang.ke.com/loupan/pg1>
Traceback (most recent call last):
  File "C:\Users\requests\Anaconda3\envs\spider\lib\site-packages\twisted\internet\defer.py", line 1416, in _inlineCallbacks
    result = result.throwExceptionIntoGenerator(g)
  File "C:\Users\requests\Anaconda3\envs\spider\lib\site-packages\twisted\python\failure.py", line 491, in throwExceptionIntoGenerator
    return g.throw(self.type, self.value, self.tb)
  File "C:\Users\requests\Anaconda3\envs\spider\lib\site-packages\scrapy\core\downloader\middleware.py", line 43, in process_request
    defer.returnValue((yield download_func(request=request,spider=spider)))
  File "C:\Users\requests\Anaconda3\envs\spider\lib\site-packages\twisted\internet\defer.py", line 654, in _runCallbacks
    current.result = callback(current.result, *args, **kw)
  File "C:\Users\requests\Anaconda3\envs\spider\lib\site-packages\twisted\internet\endpoints.py", line 975, in startConnectionAttempts
    "no results for hostname lookup: {}".format(self._hostStr)
twisted.internet.error.DNSLookupError: DNS lookup failed: no results for hostname lookup: xan.fang.ke.com.
